Workbook

Sheet 合规问卷 - 基础问题
A1: 号 | B1: 合规评审问题 | C1: 需求方回答反馈 & 说明（需需求方勾选，或填写补充信息） | D1: 勾选 | E1: 安全合规填写
A2: 4 | B2: 产品 / 业务是否涉及：针对儿童的个人数据的收集 / 处理？ 注：儿童：未满 14 周岁的个人 | C2: 否，不涉及针对儿童的个人数据收集 / 处理功能和行为 | D2: FALSE | E2: 其他信息，请在此补充说明：
C3: 是，存在如下儿童数据处理行为 | D3: FALSE
A4: 5.1 | B4: 产品 / 业务是否涉及个性化功能 / 场景？ | C4: 否，个性化功能场景不涉及 | D4: FALSE | E4: 其他信息，请在此补充说明：
C5: 是，存在个性化功能场景 | D5: FALSE
A6: 5.2 | B6: 产品 / 业务是否涉及在中国境内，利用深度内容合成技术提供服务？ | C6: 否，以下 "深度内容合成" 技术相关的功能 / 场景 / 数据处理活动均不涉及 | D6: FALSE | E6: 其他信息，请在此补充说明：
C7: 是，存在深度内容合成技术，即利用深度学习、虚拟现实等生成合成类算法制作文本、图像、音频、视频、虚拟场景等网络信息的技术，包括： | D7: FALSE
A8: 5.3 | B8: 产品 / 业务是否涉及在中国境内使用算法推荐技术，提供互联网信息服务？ | C8: 否，以下 "算法推荐" 相关的功能 / 场景 / 数据处理活动均不涉及 | D8: FALSE | E8: 其他信息，请在此补充说明：
C9: 是，存在利用算法推荐技术向中国境内提供产品服务，包括： | D9: FALSE
A10: 5.4 | B10: 产品 / 业务是否涉及利用生成式人工智能（AI）即：基于算法、模型、规则，生成文本、图片、声音、视频、代码等内容；并面向中国境内公众提供产品 / 服务？ | C10: 否，不涉及利用 “生成式人工智能技术” 向中国境内提供生成文本、图片、音频、视频等内容的服务 | D10: FALSE | E10: 其他信息，请在此补充说明：
C11: o 不涉及生成式人工智能 AI 模型 | D11: FALSE
C12: o 不对外提供 AI 服务，仅对声网内部提供服务 | D12: FALSE
C13: o 不对中国境内提供 AIGC 模型 / 服务 | D13: FALSE
C14: 是，涉及利用 “生成式人工智能技术” 向中国境内提供产品服务（生成文本、图片、音频、视频等内容） | D14: FALSE
A15: 6 | B15: 产品 / 业务是否涉及从境内访问境外 ChatGPT 的代理服务？ | C15: 否，不涉及提供任何代理服务 / 产品等，使用户能够从中国境内访问境外 ChatGPT、OpenAI 等智能聊天工具服务 | D15: FALSE | E15: 其他信息，请在此补充说明：
C16: 是，涉及提供代理服务 / 产品等，使用户能够从中国境内访问境外 ChatGPT、OpenAI 的代理服务 | D16: FALSE
A17: 7 | B17: 产品 / 业务收集的个人信息存储在什么国家 / 区域？ 备注：日志信息包括不限于：设备类型、设备型号、CPU 信息、电池电量信息、操作系统信息；IP 地址、网络类型；UID、CID、用户属性、频道信息、使用时长、频道内设置名称等日志 | C17: 终端用户 - 网络 / 设备标识、操作日志数据（参考右侧备注） | E17: 其他信息，请在此补充说明：
C18: o 不存储日志数据 | D18: FALSE
C19: o 存储部署 / 上报在：存储在本地并加密 | D19: FALSE
C20: 终端用户 - 传输内容数据：（音频 / 视频录制内容；历史消息；图片 / 抽帧；文件等），数据部署存储在： | E20: 其他信息，请在此补充说明：
C21: o 不存储日志数据 | D21: FALSE
C22: o 存储部署 / 上报在： | D22: FALSE
C23: （企业）客户 / 开发者 - 注册 / 联系人信息（如：姓名、手机号、邮箱、银行账号等），数据部署存储在： | E23: 其他信息，请在此补充说明：
C24: o 不存储日志数据 | D24: FALSE
C25: o 存储部署 / 上报在： | D25: FALSE
A26: 8 | B26: 产品的功能是否满足设计、默认隐私和安全原则？ | C26: 1. 数据传输安全 - 传输通道加密
C27: 否，传输通道尚无加密机制 | D27: FALSE
C28: 是，传输通道有加密机制： | D28: FALSE
C29: 2. 数据传输安全 - 传输内容加密（如：音视频媒体流、消息等）
C30: 否，产品尚未让客户选择自行对传输内容进行加密 | D30: FALSE
C31: 是，客户可以选择自行对传输内容加密 | D31: FALSE
C32: 3. 数据存储安全 - 存储数据加密（用户 / 客户的敏感个人信息；或内容数据）
C33: 否。存储用户 / 客户的敏感个人信息或内容数据，但尚未对数据进行存储加密 | D33: FALSE
C34: 是，产品对用户 / 客户的敏感个人信息或内容数据，采取了存储加密 | D34: FALSE
C35: N/A，产品不涉及存储用户 / 客户敏感个人信息或内容数据 | D35: FALSE
C36: 4. 数据存储安全 - 存储密钥是否由客户控制
C37:  否。数据存储在声网云服务；声网团队管理云存储密钥，并对用户内容数据有访问 / 读的权限 | D37: FALSE
C38:  是。数据存储在声网云服务；云存储密钥仅由客户控制；声网对用户内容数据没有访问 / 读权限 | D38: FALSE
C39:  N/A，用户内容数据，不存储在声网，仅存储在客户指定的云服务 | D39: FALSE
C40:  N/A，产品不涉及数据存储功能 | D40: FALSE
...

Sheet SDK信息收集&权限基本信息
A1: 个人信息类型 | B1: 目的和用途 | C1: 必要或可选 | D1: 处理方式 | E1: 操作系统
A12: 权限类型 | B12: 目的和用途 | C12: 必选或可选 | D12: 操作系统

Sheet 个人信息收集情况
B1: 仅需依据情况勾选此列 | H1: 仅需依据情况勾选此列
B2: 是否收集 | C2: 是否需要填写 | D2: 个人信息主体 | E2: 信息分类 | F2: 具体信息项 | G2: 是否敏感 | H2: 是否收集
C3: =B3 -> 0 | D3: 企业客户或者开发者 | E3: 基本个人信息 | F3: 姓名 | G3: 否 | H3: FALSE
D4: 企业客户或者开发者 | E4: 基本个人信息 | F4: 手机号 / 个人电话号码 | G4: 否 | H4: FALSE
D5: 企业客户或者开发者 | E5: 基本个人信息 | F5: 电子邮件地址 | G5: 否 | H5: FALSE
D6: 企业客户或者开发者 | E6: 基本个人信息 | F6: 第三方账号信息（如：微信号等） | G6: 否 | H6: FALSE
D7: 企业客户或者开发者 | E7: 基本个人信息 | F7: 头像 | G7: 否 | H7: FALSE
D8: 企业客户或者开发者 | E8: 基本个人信息 | F8: 昵称 | G8: 否 | H8: FALSE
D9: 企业客户或者开发者 | E9: 基本个人信息 | F9: 年龄 | G9: 否 | H9: FALSE
D10: 企业客户或者开发者 | E10: 基本个人信息 | F10: 生日 | G10: 否 | H10: FALSE
D11: 企业客户或者开发者 | E11: 基本个人信息 | F11: 性别 | G11: 否 | H11: FALSE
D12: 企业客户或者开发者 | E12: 基本个人信息 | F12: 民族 | G12: 否 | H12: FALSE
D13: 企业客户或者开发者 | E13: 基本个人信息 | F13: 国籍 | G13: 否 | H13: FALSE
D14: 企业客户或者开发者 | E14: 基本个人信息 | F14: 住址 / 通讯地址 | G14: 否 | H14: FALSE
D15: 企业客户或者开发者 | E15: 基本个人信息 | F15: 家庭关系 | G15: 否 | H15: FALSE
... D43: 企业客户或者开发者 | E43: 其他敏感个人信息 | F43: 精准定位信息 | G43: 是 | H43: FALSE
D44: 企业客户或者开发者 | E44: 其他 | F44: _____________________________ | H44: FALSE
C45: =B45 -> 0 | D45: 声网员工 | E45: 基本信息 | F45: 姓名 | G45: 否 | H45: FALSE
D46: 声网员工 | E46: 基本信息 | F46: 邮箱 | G46: 否 | H46: FALSE
D47: 声网员工 | E47: 基本信息 | F47: 手机号 | G47: 否 | H47: FALSE
D48: 声网员工 | E48: 基本信息 | F48: 年龄 | G48: 否 | H48: FALSE
D49: 声网员工 | E49: 基本信息 | F49: 性别 | G49: 否 | H49: FALSE
D50: 声网员工 | E50: 基本信息 | F50: 住址 / 通信地址 | G50: 否 | H50: FALSE
D51: 声网员工 | E51: 岗位职级信息 | F51: 岗位职级信息 | H51: FALSE
D52: 声网员工 | E52: 工作学习履历信息 | F52: 工作学习履历信息 | H52: FALSE
D53: 声网员工 | E53: 个人身份信息 | F53: 身份证 | G53: 是 | H53: FALSE
D54: 声网员工 | E54: 个人身份信息 | F54: 其他身份信息（军官证、护照、驾驶证、工作证、社保卡、居住证等） | G54: 是 | H54: FALSE
D55: 声网员工 | E55: 金融账号信息 | F55: 金融账号（如：银行账号） | G55: 是 | H55: FALSE
D56: 声网员工 | E56: 工作奖惩信息 | F56: 工作奖惩信息 | G56: 是 | H56: FALSE
D57: 声网员工 | E57: 紧急联系 / 联络人 | F57: 紧急联系 / 联络人 | G57: 是 | H57: FALSE
D58: 声网员工 | E58: 社保信息 | F58: 社保信息 | G58: 是 | H58: FALSE
D59: 声网员工 | E59: 薪酬相关信息 | F59: 薪酬相关信息（薪资 / 工资、奖金、期权、股票、RSU、股份、VPP 等） | G59: 是 | H59: FALSE
D60: 声网员工 | E60: 绩效信息 | F60: 绩效信息 | G60: 是 | H60: FALSE
D61: 声网员工 | E61: 生物特征信息 | F61: 生物特征信息（如：指纹、声纹、虹膜、人脸识别特征等） | G61: 是 | H61: FALSE
D62: 声网员工 | E62: 其他基本信息 | F62: 籍贯 | G62: 是 | H62: FALSE
D63: 声网员工 | E63: 其他基本信息 | F63: 民族 | G63: 否 | H63: FALSE
D64: 声网员工 | E64: 其他基本信息 | F64: 生理健康信息 | G64: 否 | H64: FALSE
... D73: 声网员工 | E73: 其他敏感信息 | F73: 精准定位信息 | G73: 是 | H73: FALSE
D74: 声网员工 | E74: 请补充： | F74: _____________________________ | H74: FALSE
C75: =B75 -> 0 | D75: 终端用户 | E75: 传输内容数据 | F75: 文字消息 | G75: 否 | H75: FALSE
...

Sheet RoPA(数据处理记录)
D1: 数据收集 Data Collection | K1: 数据传输 Data Transmission | O1: 数据存储 Data Storage | S1: 数据处理 Data Processing | W1: 数据删除 Data Deletion
A2: 数据主体 | B2: 数据类型 | C2: 字段 | D2: 属于个人敏感数据 | E2: 数据来源/ 收集方式 | F2: 个人数据收集/ 处理合法依据？ | G2: 个人数据处理角色（个人信息处理者 or 受托处理者） | H2: 数据收集/处理目的 | I2: 是否写入日志 | J2: 数据规模 （如：人数） | K2: 数据传输路径 （如：终端设备；边缘节点；数据系统平台；第三方服务商等） | L2: 数据传输加密措施 | M2: 若委托第三方处理数据，请填写第三方名称 （第三方-系统平台；外包服务等） | N2: 是否与第三方签署数据处理协议？ | O2: 数据是否存储？ | P2: 数据存储系统/ 第三方平台等 | Q2: 数据存储国家/区域 | R2: 数据存储加密措施 | S2: 访问控制/权限控制措施 | T2: 数据脱敏/匿名化控制措施 | U2: 系统是否记录日志？ | V2: 允许批量数据下载/导出？ | W2: 数据留存期限？ | X2: 数据删除机制？ | Y2: 数据留存原因/依据
A3: 根据“个人信息收集情况”预填写 | B3: 根据“个人信息收集情况”预填写 | C3: 根据“个人信息收集情况”预填写 | D3: 根据“个人信息收集情况”预填写 | E3: 回答参考: 1.客户/终端用户录入 2.终端用户授权提供 3.系统数据接口传入 4.SDK自动采集 …… | F3: 回答参考： 1.获得个人同意 2.遵循合同必要 3.企业合法利益 …… 4.不适用 （不属于可识别的个人信息） | G3: 回答参考： 1.个人信息处理者 2.个人信息受托处理者 | H3: 回答参考： 1.为提供XXX产品服务； 2.为网络连接； 3.为故障排查； 4.为计量统计； 5.为计费结算； 6.为客户管理/商机管理； 7.为个人画像分析； 8.为营销推广； …… | I3: 是/否 | J3: 回答参考： 中国大陆注册客户人数 美国/ROW注册客户人数 …… | K3: 回答参考： 1.客户录入注册信息→ 官网Console平台→ XX服务器→ 第三方客户商机系统A / 公司内部系统B…… 或： 2.终端用户→ SDK→ 大网→ 上报数据平台→ Agora在XX国家的服务器 …… | L3: 回答参考： 1.传输通道加密： 1）采用AUT加密（Agora Universal Transport） 2）采用TLS 1.3及以上传输加密 2.传输内容加密 （如：音视频媒体流、消息等） 1）支持客户对传输内容加密（可选AES128或AES256GCM）；且密钥仅限于客户App控制 2）支持客户对传输内容加密（可选AES128或AES256GCM）；但是密钥由声网有最小必要权限的研发团队管理 | M3: 回答参考： 数据传输给： 1）第三方云服务商XX； 2）第三方应用系统/数据库XX； 3）第三方API/SDK服务XX； 4）第三方外包公司XX； …… | N3: 回答参考： 是/否 | O3: 回答参考： 1.否-数据不会存储； 2.是-数据落盘存储 3.是-数据仅缓存 …… | P3: 回答参考： 1.不适用-数据不会存储； 2.数据存储在XX国家区域的Agora系统/数据库； 3.数据存储在XX第三方系统平台/云服务 …… | Q3: 回答参考： 1.中国大陆； 2.美国； 3.欧盟； 4.其他 …… | R3: 回答参考： 1.不适用 - 不涉及存储敏感数据 2.采用AES 128 或AES 256 GCM存储加密 3.采用第三方云服务加密存储服务（如：AWS S3加密） 4.采用其他KMS加密服务 …… | S3: 回答参考： 1.声网不会访问用户传输内容数据 2.声网内部，仅最少且必要的中国XXX部门团队才能访问； 3.声网内部，仅最少且必要的美国XXX部门团队才能访问 …… | T3: 回答参考： 1.不适用-不属于可识别的个人信息，无需匿名化 2.采用脱敏展示（如：星号*） 3.泛化展示（如：只查询展示区间/范围数据；或统计数据） 4.采用匿名化处理 …… | U3: 回答参考： 是，系统有日志记录； 日志至少保存XX个月 | V3: 回答参考： 否。禁止/限制批量下载或导出权限 | W3: 回答参考： 1.不适用-数据不会存储 2.客户/开发者注销或删除账号，则数据删除 3.存储期限30天（30天会定期清理数据） 4.存储期限由客户配置选择 - 如：7天/30天/90天/180天 （到期删除数据） 5.尚未定义数据存储期限 …… | X3: 回答参考： 1.不适用-数据不存储 2.客户联系人注销后删除； 3.存储30天定期清理 4.存储期限由客户配置选择（到期删除） 5.不会删除 …… | Y3: N/A
A4: {=IFERROR(INDEX(_xlfn._xlws.FILTER(个人信息收集情况!D:G,个人信息收集情况!H:H=TRUE),ROW(个人信息收集情况!D1)),"")} | L4: 采用AUT加密（Agora Universal Transport） 支持客户对传输内容加密（可选AES128或AES256GCM）；且密钥仅限于客户App控制 | M4: N/A. | N4: N/A. | P4: N/A | Q4: N/A | R4: N/A. | S4: N/A. 声网没有访问权限 | T4: N/A | U4: N/A | V4: N/A | W4: N/A | X4: N/A | Y4: N/A
A5: {=IFERROR(INDEX(_xlfn._xlws.FILTER(个人信息收集情况!D:G,个人信息收集情况!H:H=TRUE),ROW(个人信息收集情况!D2)),"")} | L5: 采用AUT加密（Agora Universal Transport） 支持客户对传输内容加密（可选AES128或AES256GCM）；且密钥仅限于客户App控制 | M5: N/A. | N5: N/A. | P5: N/A | Q5: N/A | R5: N/A. | S5: N/A. 声网没有访问权限 | T5: N/A | U5: N/A | V5: N/A | W5: N/A | X5: N/A | Y5: N/A
A6: {=IFERROR(INDEX(_xlfn._xlws.FILTER(个人信息收集情况!D:G,个人信息收集情况!H:H=TRUE),ROW(个人信息收集情况!D3)),"")} | L6: 采用AUT加密（Agora Universal Transport） | M6: N/A. | N6: N/A. | O6: 是 | P6: Agora Data Platform | Q6: USA | R6: No | S6: 产研团队（满足最小必要性）可以访问运营数据，仅在解决问题和查错时使用 | T6: 否，不属个人信息 | U6: 是 | V6: 无 | W6: 30天 | X6: 存储30天定期清理 | Y6: NA
A7: {=IFERROR(INDEX(_xlfn._xlws.FILTER(个人信息收集情况!D:G,个人信息收集情况!H:H=TRUE),ROW(个人信息收集情况!D4)),"")} | L7: 采用AUT加密（Agora Universal Transport） | M7: N/A. | N7: N/A. | O7: 是 | P7: Agora Data Platform | Q7: USA | R7: No | T7: 否，不属个人信息 | U7: 是 | V7: 无 | W7: 30天 | X7: 存储30天定期清理 | Y7: NA
A8: {=IFERROR(INDEX(_xlfn._xlws.FILTER(个人信息收集情况!D:G,个人信息收集情况!H:H=TRUE),ROW(个人信息收集情况!D5)),"")} | L8: 采用AUT加密（Agora Universal Transport） | M8: N/A. | N8: N/A. | O8: 是 | P8: Agora Data Platform | Q8: USA | R8: No | T8: 否，不属个人信息 | U8: 是 | V8: 无 | W8: 30天 | X8: 存储30天定期清理 | Y8: NA
A9: {=IFERROR(INDEX(_xlfn._xlws.FILTER(个人信息收集情况!D:G,个人信息收集情况!H:H=TRUE),ROW(个人信息收集情况!D6)),"")} | L9: 采用AUT加密（Agora Universal Transport） | M9: N/A. | N9: N/A. | O9: 是 | P9: Agora Data Platform | Q9: USA | R9: No | T9: 否，不属个人信息 | U9: 是 | V9: 无 | W9: 30天 | X9: 存储30天定期清理 | Y9: NA
A10: {=IFERROR(INDEX(_xlfn._xlws.FILTER(个人信息收集情况!D:G,个人信息收集情况!H:H=TRUE),ROW(个人信息收集情况!D7)),"")} | L10: 采用AUT加密（Agora Universal Transport） | M10: N/A. | N10: N/A. | O10: 是 | P10: Agora Data Platform | Q10: USA | R10: No | T10: 否，不属个人信息 | U10: 是 | V10: 无 | W10: 30天 | X10: 存储30天定期清理 | Y10: NA
A11: {=IFERROR(INDEX(_xlfn._xlws.FILTER(个人信息收集情况!D:G,个人信息收集情况!H:H=TRUE),ROW(个人信息收集情况!D8)),"")} | L11: 采用AUT加密（Agora Universal Transport） | M11: N/A. | N11: N/A. | O11: 是 | P11: Agora Data Platform | Q11: USA | R11: No | T11: 否 | U11: 是 | V11: 无 | W11: 30天 | X11: 存储30天定期清理 | Y11: NA
A12: {=IFERROR(INDEX(_xlfn._xlws.FILTER(个人信息收集情况!D:G,个人信息收集情况!H:H=TRUE),ROW(个人信息收集情况!D9)),"")} | L12: 采用AUT加密（Agora Universal Transport） | M12: N/A. | N12: N/A. | O12: 是 | P12: Agora Data Platform | Q12: USA | R12: No | T12: 否，不属个人信息 | U12: 是 | V12: 无 | W12: 30天 | X12: 存储30天定期清理 | Y12: NA
A13: {=IFERROR(INDEX(_xlfn._xlws.FILTER(个人信息收集情况!D:G,个人信息收集情况!H:H=TRUE),ROW(个人信息收集情况!D10)),"")} | L13: 采用AUT加密（Agora Universal Transport） | M13: N/A. | N13: N/A. | O13: 是 | P13: Agora Data Platform | Q13: USA | R13: No | T13: 否 | U13: 是 | V13: 无 | W13: 30天 | X13: 存储30天定期清理 | Y13: NA
A14: {=IFERROR(INDEX(_xlfn._xlws.FILTER(个人信息收集情况!D:G,个人信息收集情况!H:H=TRUE),ROW(个人信息收集情况!D11)),"")} | L14: 采用AUT加密（Agora Universal Transport） | M14: N/A. | N14: N/A. | O14: 是 | P14: Agora Data Platform | Q14: USA | R14: No | T14: 否，不属个人信息 | U14: 是 | V14: 无 | W14: 30天 | X14: 存储30天定期清理 | Y14: NA
A15: {=IFERROR(INDEX(_xlfn._xlws.FILTER(个人信息收集情况!D:G,个人信息收集情况!H:H=TRUE),ROW(个人信息收集情况!D12)),"")} | L15: 采用AUT加密（Agora Universal Transport） | M15: N/A. | N15: N/A. | O15: 是 | P15: Agora Data Platform | Q15: USA | R15: No | T15: 否，不属个人信息 | U15: 是 | V15: 无 | W15: 31天 | X15: 存储30天定期清理 | Y15: NA
A16: {=IFERROR(INDEX(_xlfn._xlws.FILTER(个人信息收集情况!D:G,个人信息收集情况!H:H=TRUE),ROW(个人信息收集情况!D13)),"")} | B16: {=IFERROR(INDEX(_xlfn._xlws.FILTER(个人信息收集情况!E:F,个人信息收集情况!H:H=TRUE),ROW(个人信息收集情况!D14)),"")}
A17: {=IFERROR(INDEX(_xlfn._xlws.FILTER(个人信息收集情况!D:G,个人信息收集情况!H:H=TRUE),ROW(个人信息收集情况!D14)),"")} | B17: {=IFERROR(INDEX(_xlfn._xlws.FILTER(个人信息收集情况!E:F,个人信息收集情况!H:H=TRUE),ROW(个人信息收集情况!D15)),"")}
A18: {=IFERROR(INDEX(_xlfn._xlws.FILTER(个人信息收集情况!D:G,个人信息收集情况!H:H=TRUE),ROW(个人信息收集情况!D15)),"")} | B18: {=IFERROR(INDEX(_xlfn._xlws.FILTER(个人信息收集情况!E:F,个人信息收集情况!H:H=TRUE),ROW(个人信息收集情况!D16)),"")}
A19: {=IFERROR(INDEX(_xlfn._xlws.FILTER(个人信息收集情况!D:G,个人信息收集情况!H:H=TRUE),ROW(个人信息收集情况!D16)),"")} | B19: {=IFERROR(INDEX(_xlfn._xlws.FILTER(个人信息收集情况!E:F,个人信息收集情况!H:H=TRUE),ROW(个人信息收集情况!D17)),"")}
A20: {=IFERROR(INDEX(_xlfn._xlws.FILTER(个人信息收集情况!D:G,个人信息收集情况!H:H=TRUE),ROW(个人信息收集情况!D17)),"")} | B20: {=IFERROR(INDEX(_xlfn._xlws.FILTER(个人信息收集情况!E:F,个人信息收集情况!H:H=TRUE),ROW(个人信息收集情况!D18)),"")}
A21: {=IFERROR(INDEX(_xlfn._xlws.FILTER(个人信息收集情况!D:G,个人信息收集情况!H:H=TRUE),ROW(个人信息收集情况!D18)),"")} | B21: {=IFERROR(INDEX(_xlfn._xlws.FILTER(个人信息收集情况!E:F,个人信息收集情况!H:H=TRUE),ROW(个人信息收集情况!D19)),"")}
A22: {=IFERROR(INDEX(_xlfn._xlws.FILTER(个人信息收集情况!D:G,个人信息收集情况!H:H=TRUE),ROW(个人信息收集情况!D19)),"")} | B22: {=IFERROR(INDEX(_xlfn._xlws.FILTER(个人信息收集情况!E:F,个人信息收集情况!H:H=TRUE),ROW(个人信息收集情况!D20)),"")}
A23: {=IFERROR(INDEX(_xlfn._xlws.FILTER(个人信息收集情况!D:G,个人信息收集情况!H:H=TRUE),ROW(个人信息收集情况!D20)),"")} | B23: {=IFERROR(INDEX(_xlfn._xlws.FILTER(个人信息收集情况!E:F,个人信息收集情况!H:H=TRUE),ROW(个人信息收集情况!D21)),"")}
A24: {=IFERROR(INDEX(_xlfn._xlws.FILTER(个人信息收集情况!D:G,个人信息收集情况!H:H=TRUE),ROW(个人信息收集情况!D21)),"")} | B24: {=IFERROR(INDEX(_xlfn._xlws.FILTER(个人信息收集情况!E:F,个人信息收集情况!H:H=TRUE),ROW(个人信息收集情况!D22)),"")}
A25: {=IFERROR(INDEX(_xlfn._xlws.FILTER(个人信息收集情况!D:G,个人信息收集情况!H:H=TRUE),ROW(个人信息收集情况!D22)),"")} | B25: {=IFERROR(INDEX(_xlfn._xlws.FILTER(个人信息收集情况!E:F,个人信息收集情况!H:H=TRUE),ROW(个人信息收集情况!D23)),"")}
A26: {=IFERROR(INDEX(_xlfn._xlws.FILTER(个人信息收集情况!D:G,个人信息收集情况!H:H=TRUE),ROW(个人信息收集情况!D23)),"")} | B26: {=IFERROR(INDEX(_xlfn._xlws.FILTER(个人信息收集情况!E:F,个人信息收集情况!H:H=TRUE),ROW(个人信息收集情况!D24)),"")}
A27: {=IFERROR(INDEX(_xlfn._xlws.FILTER(个人信息收集情况!D:G,个人信息收集情况!H:H=TRUE),ROW(个人信息收集情况!D25)),"")} | B27: {=IFERROR(INDEX(_xlfn._xlws.FILTER(个人信息收集情况!E:F,个人信息收集情况!H:H=TRUE),ROW(个人信息收集情况!D25)),"")}
A28: {=IFERROR(INDEX(_xlfn._xlws.FILTER(个人信息收集情况!D:G,个人信息收集情况!H:H=TRUE),ROW(个人信息收集情况!D26)),"")} | B28: {=IFERROR(INDEX(_xlfn._xlws.FILTER(个人信息收集情况!E:F,个人信息收集情况!H:H=TRUE),ROW(个人信息收集情况!D26)),"")}
A29: {=IFERROR(INDEX(_xlfn._xlws.FILTER(个人信息收集情况!D:G,个人信息收集情况!H:H=TRUE),ROW(个人信息收集情况!D27)),"")} | B29: {=IFERROR(INDEX(_xlfn._xlws.FILTER(个人信息收集情况!E:F,个人信息收集情况!H:H=TRUE),ROW(个人信息收集情况!D27)),"")}
A30: {=IFERROR(INDEX(_xlfn._xlws.FILTER(个人信息收集情况!D:G,个人信息收集情况!H:H=TRUE),ROW(个人信息收集情况!D28)),"")} | B30: {=IFERROR(INDEX(_xlfn._xlws.FILTER(个人信息收集情况!F:F,个人信息收集情况!H:H=TRUE),ROW(个人信息收集情况!D28)),"")}
A31: {=IFERROR(INDEX(_xlfn._xlws.FILTER(个人信息收集情况!D:G,个人信息收集情况!H:H=TRUE),ROW(个人信息收集情况!D29)),"")} | B31: {=IFERROR(INDEX(_xlfn._xlws.FILTER(个人信息收集情况!F:F,个人信息收集情况!H:H=TRUE),ROW(个人信息收集情况!D29)),"")}
A32: {=IFERROR(INDEX(_xlfn._xlws.FILTER(个人信息收集情况!D:G,个人信息收集情况!H:H=TRUE),ROW(个人信息收集情况!D30)),"")} | B32: {=IFERROR(INDEX(_xlfn._xlws.FILTER(个人信息收集情况!F:F,个人信息收集情况!H:H=TRUE),ROW(个人信息收集情况!D30)),"")}
A33: {=IFERROR(INDEX(_xlfn._xlws.FILTER(个人信息收集情况!D:G,个人信息收集情况!H:H=TRUE),ROW(个人信息收集情况!D31)),"")} | B33: {=IFERROR(INDEX(_xlfn._xlws.FILTER(个人信息收集情况!F:F,个人信息收集情况!H:H=TRUE),ROW(个人信息收集情况!D31)),"")}
A34: {=IFERROR(INDEX(_xlfn._xlws.FILTER(个人信息收集情况!D:G,个人信息收集情况!H:H=TRUE),ROW(个人信息收集情况!D32)),"")} | B34: {=IFERROR(INDEX(_xlfn._xlws.FILTER(个人信息收集情况!F:F,个人信息收集情况!H:H=TRUE),ROW(个人信息收集情况!D32)),"")}
A35: {=IFERROR(INDEX(_xlfn._xlws.FILTER(个人信息收集情况!D:G,个人信息收集情况!H:H=TRUE),ROW(个人信息收集情况!D33)),"")} | B35: {=IFERROR(INDEX(_xlfn._xlws.FILTER(个人信息收集情况!F:F,个人信息收集情况!H:H=TRUE),ROW(个人信息收集情况!D33)),"")}
A36: {=IFERROR(INDEX(_xlfn._xlws.FILTER(个人信息收集情况!D:G,个人信息收集情况!H:H=TRUE),ROW(个人信息收集情况!D34)),"")} | B36: {=IFERROR(INDEX(_xlfn._xlws.FILTER(个人信息收集情况!F:F,个人信息收集情况!H:H=TRUE),ROW(个人信息收集情况!D34)),"")}
A37: {=IFERROR(INDEX(_xlfn._xlws.FILTER(个人信息收集情况!D:G,个人信息收集情况!H:H=TRUE),ROW(个人信息收集情况!D35)),"")} | B37: {=IFERROR(INDEX(_xlfn._xlws.FILTER(个人信息收集情况!F:F,个人信息收集情况!H:H=TRUE),ROW(个人信息收集情况!D35)),"")}
A38: {=IFERROR(INDEX(_xlfn._xlws.FILTER(个人信息收集情况!D:G,个人信息收集情况!H:H=TRUE),ROW(个人信息收集情况!D36)),"")} | B38: {=IFERROR(INDEX(_xlfn._xlws.FILTER(个人信息收集情况!F:F,个人信息收集情况!H:H=TRUE),ROW(个人信息收集情况!D36)),"")}
A39: {=IFERROR(INDEX(_xlfn._xlws.FILTER(个人信息收集情况!D:G,个人信息收集情况!H:H=TRUE),ROW(个人信息收集情况!D37)),"")} | B39: {=IFERROR(INDEX(_xlfn._xlws.FILTER(个人信息收集情况!F:F,个人信息收集情况!H:H=TRUE),ROW(个人信息收集情况!D37)),"")}
A40: {=IFERROR(INDEX(_xlfn._xlws.FILTER(个人信息收集情况!D:G,个人信息收集情况!H:H=TRUE),ROW(个人信息收集情况!D38)),"")} | B40: {=IFERROR(INDEX(_xlfn._xlws.FILTER(个人信息收集情况!F:F,个人信息收集情况!H:H=TRUE),ROW(个人信息收集情况!D38)),"")}
...

Sheet 第三方清单
A1: 服务名称 | B1: 使用目的和用途 | C1: 信息共享字段 | D1: 第三方名称 | E1: 安全处理方式 | F1: 第三方隐私政策链接 | G1: 是否通过第三方评审 | H1: 第三方安全评审记录
A2: 例：阿里云/美颜SDK | B2: 例：使用云服务/引入美颜功能 | E2: 加密传输/不加密传输等

Sheet 第三方安全评审模板
A1: 第三方信息安全和隐私合规自检表
A2: 序号 | B2: 评估项 | C2: 回答（是/否/不适用） | D2: 补充/解释说明 | E2: 相关文件/证明材料
A3: 1、安全认证
A4: 1 | B4: 第三方是否具备网络安全、信息安全、个人信息/隐私保护相关的资质认证？包括： • 网络安全等级保护（三级）测评报告 • ISO认证（ISO27001信息安全、ISO27701隐私管理；ISO27017、ISO27018、ISO22301等） • SOC 2 / SOC3 鉴证服务报告 • 其他安全合规资质/认证/报告
A5: 2 | B5: 第三方是否与声网签订了保密协议？
A6: 3 | B6: 如果第三方提供的是外包服务（专项），外包项目相关人员是否签署了保密协议？
A8: 2、人员安全
A9: 1 | B9: 第三方供应商是否对员工实施安全管控？包括： 对离职人员的：系统权限及时禁用、设备资产及时回收、签署必要的离职保密承诺书等？
A10: 2 | B10: 第三方供应商是否定期对员工开展信息安全和隐私数据保护相关的培训？
A12: 3、物理安全
A13: 1 | B13: 第三方的数据中心（服务器/数据库等）是否部署在中国境内?
A14: 2 | B14: 第三方的数据中心是否满足物理安全要求?（遵循网络安全等级保护、ISO27001等标准要求）
A16: 4、访问控制安全
A17: 1 | B17: 第三方是否建立访问控制制度要求，并且确保安全的登录/身份验证机制？
A18: 2 | B18: 第三方是否使用了强的密码策略，包括：密码长度（8位以上）、复杂度（包括大写字母、小写字母、数字、特殊字符）、定期更新等
A19: 3 | B19: 第三方是否控制访问权限，并严格限制仅最少且必要的人员才能访问系统？
A20: 4 | B20: 第三方是否限制人员批量下载/导出/操作系统数据？
A21: 5 | B21: 第三方人员离职时，是否及时删除系统/数据的访问权限；回收其所有资产设备？
A22: 6 | B22: 第三方是否开启系统操作日志？并定期开展日志审计？
A23: 7 | B23: 第三方是否定期对数据系统开展权限复核和审阅？
A24: 8 | B24: 第三方是否允许远程访问系统数据? 远程访问是否通过VPN/白名单控制？并且需严格授权审批？
A26: 5、开发运维安全（针对外包开发或引入第三方系统等）
A27: 1 | B27: 第三方提供的产品/服务上线前是否开展安全合规评估、个人信息影响评估?
A28: 2 | B28: 第三方对自己所提供的产品/服务，是否（聘请专业测评机构）定期开展渗透测试、漏洞扫描？ 请第三方提供（专业测评机构）特定产品/服务的渗透测试报告和漏洞扫描报告。
A29: 3 | B29: 第三方是否及时扫描/检测产品服务的安全漏洞，并在上线前及时解决安全漏洞？
A30: 4 | B30: 第三方提供的产品/服务上线前是否经过代码安全审查？
A31: 5 | B31: 第三方的产品/服务如果涉及采用开源工具进行程序开发，是否对开源工具采取了管理措施，以确保开源工具的安全性？
A32: 6 | B32: 第三方是否制定了安全补丁管理流程？并且确保及时管理和更新补丁？
A34: 6、事件应急响应及业务连续性
A35: 1 | B35: 第三方是否制定了应急预案及事件响应流程？（包括应急响应时间目标-SLA）
A36: 2 | B36: 第三方是否采取技术手段对安全事件监测和预警？
A37: 3 | B37: 第三方是否每年开展应急预案培训、演练？
A38: 4 | B38: 第三方过去是否曾发生过重大信息安全事件或数据泄露事件？ 如果有，请具体说明。
A39: 5 | B39: 第三方如果发生信息安全或数据泄露事件，如何确保及时通知声网？是否建立流程机制？
A41: 7、网络安全
A42: 1 | B42: 第三方是否部署了防火墙、入侵防御和入侵检测系统（IDS/IPS）？
A43: 2 | B43: 第三方是否采取安全技术手段来预防DDOS等外部攻击？
A44: 3 | B44: 第三方生产网络隔离是否与办公网络隔离？
A46: 8、数据安全
A47: 1 | B47: 第三方是否根据国家监管要求制定了数据分类分级制度？并对不同级别的数据，采取了分级保护的安全管控措施？
...
